Workbook

Sheet Project Guide
A1: PR. 1 Fundamental Booster
A2: Topics:
A3: - Relative & Absolute References, Formatting, Data Input
A4: - IF Formulas, Nested IFs, IF with AND/OR
A5: - COUNTIFS, SUMIFS, AVERAGEIFS
A6: - Lookup Functions (VLOOKUP, XLOOKUP, XMATCH)
A7: - INDEX/MATCH for dynamic searches
A8: - TEXT Functions for string manipulations
A9: - INDIRECT and OFFSET for dynamic references
A10: - Date/Time, Math Functions, FILTER function
A12: Main Tasks:
A13: 1. Apply IF formulas to classify student grades.
... A75: Project Note: Product Price/Product Code and Date of Birth fields are not present in the supplied datasets; these two tasks are documented in the Task Solutions sheet.

Sheet Employee Data
A1: Employee ID | B1: Name | C1: Department | D1: Salary | E1: Joining Date | F1: Joining Year | G1: Joining Month | H1: Salary +10% | J1: Absolute Reference Input
A2: 3001 | B2: Employee 1 | C2: Finance | D2: 86766 | E2: 42005 | F2: =YEAR(E2) -> 2015 | G2: =TEXT(E2,"mmmm") -> January | H2: =D2*(1+$J$2) -> 95442.6 | J2: 0.1
A3: 3002 | B3: Employee 2 | C3: Finance | D3: 31943 | E3: 42255 | F3: =YEAR(E3) -> 2015 | G3: =TEXT(E3,"mmmm") -> September | H3: =D3*(1+$J$2) -> 35137.3 | J3: Used by Salary +10% formulas as $J$2
A4: 3003 | B4: Employee 3 | C4: HR | D4: 63374 | E4: 42505 | F4: =YEAR(E4) -> 2016 | G4: =TEXT(E4,"mmmm") -> May | H4: =D4*(1+$J$2) -> 69711.4
A5: 3004 | B5: Employee 4 | C5: Finance | D5: 109972 | E5: 42755 | F5: =YEAR(E5) -> 2017 | G5: =TEXT(E5,"mmmm") -> January | H5: =D5*(1+$J$2) -> 120969.2
A6: 3005 | B6: Employee 5 | C6: IT | D6: 54149 | E6: 43005 | F6: =YEAR(E6) -> 2017 | G6: =TEXT(E6,"mmmm") -> September | H6: =D6*(1+$J$2) -> 59563.9
A7: 3006 | B7: Employee 6 | C7: IT | D7: 78689 | E7: 43255 | F7: =YEAR(E7) -> 2018 | G7: =TEXT(E7,"mmmm") -> June | H7: =D7*(1+$J$2) -> 86557.9
A8: 3007 | B8: Employee 7 | C8: Marketing | D8: 35960 | E8: 43505 | F8: =YEAR(E8) -> 2019 | G8: =TEXT(E8,"mmmm") -> February | H8: =D8*(1+$J$2) -> 39556
A9: 3008 | B9: Employee 8 | C9: IT | D9: 91659 | E9: 43755 | F9: =YEAR(E9) -> 2019 | G9: =TEXT(E9,"mmmm") -> October | H9: =D9*(1+$J$2) -> 100824.9
A10: 3009 | B10: Employee 9 | C10: IT | D10: 90423 | E10: 44005 | F10: =YEAR(E10) -> 2020 | G10: =TEXT(E10,"mmmm") -> June | H10: =D10*(1+$J$2) -> 99465.3
A11: 3010 | B11: Employee 10 | C11: HR | D11: 107877 | E11: 44255 | F11: =YEAR(E11) -> 2021 | G11: =TEXT(E11,"mmmm") -> February | H11: =D11*(1+$J$2) -> 118664.7
A12: 3011 | B12: Employee 11 | C12: Finance | D12: 107634 | E12: 44505 | F12: =YEAR(E12) -> 2021 | G12: =TEXT(E12,"mmmm") -> November | H12: =D12*(1+$J$2) -> 118397.4
A13: 3012 | B13: Employee 12 | C13: Finance | D13: 35226 | E13: 44755 | F13: =YEAR(E13) -> 2022 | G13: =TEXT(E13,"mmmm") -> July | H13: =D13*(1+$J$2) -> 38748.6
A14: 3013 | B14: Employee 13 | C14: HR | D14: 40872 | E14: 45005 | F14: =YEAR(E14) -> 2023 | G14: =TEXT(E14,"mmmm") -> March | H14: =D14*(1+$J$2) -> 44959.2
A15: 3014 | B15: Employee 14 | C15: HR | D15: 55378 | E15: 45255 | F15: =YEAR(E15) -> 2023 | G15: =TEXT(E15,"mmmm") -> November | H15: =D15*(1+$J$2) -> 60915.8
... A21: 3020 | B21: Employee 20 | C21: Marketing | D21: 99924 | E21: 46755 | F21: =YEAR(E21) -> 2028 | G21: =TEXT(E21,"mmmm") -> January | H21: =D21*(1+$J$2) -> 109916.4

Sheet Sales Data
A1: Sales ID | B1: Product | C1: Region | D1: Salesperson | E1: Amount | F1: Date | G1: Month | H1: Discount % | I1: Discount Amount
A2: 2001 | B2: Keyboard | C2: South | D2: Person 1 | E2: 7048 | F2: 44927 | G2: =TEXT(F2,"mmmm") -> January | H2: =IF(E2>=40000,20%,IF(E2>=20000,10%,5%)) -> 0.05 | I2: =E2*H2 -> 352.4
A3: 2002 | B3: Printer | C3: West | D3: Person 2 | E3: 17428 | F3: 44942 | G3: =TEXT(F3,"mmmm") -> January | H3: =IF(E3>=40000,20%,IF(E3>=20000,10%,5%)) -> 0.05 | I3: =E3*H3 -> 871.4
A4: 2003 | B4: Mouse | C4: South | D4: Person 3 | E4: 23672 | F4: 44957 | G4: =TEXT(F4,"mmmm") -> January | H4: =IF(E4>=40000,20%,IF(E4>=20000,10%,5%)) -> 0.1 | I4: =E4*H4 -> 2367.2
A5: 2004 | B5: Printer | C5: East | D5: Person 4 | E5: 5264 | F5: 44972 | G5: =TEXT(F5,"mmmm") -> February | H5: =IF(E5>=40000,20%,IF(E5>=20000,10%,5%)) -> 0.05 | I5: =E5*H5 -> 263.2
A6: 2005 | B6: Keyboard | C6: North | D6: Person 5 | E6: 43388 | F6: 44987 | G6: =TEXT(F6,"mmmm") -> March | H6: =IF(E6>=40000,20%,IF(E6>=20000,10%,5%)) -> 0.2 | I6: =E6*H6 -> 8677.6
A7: 2006 | B7: Mouse | C7: North | D7: Person 6 | E7: 19757 | F7: 45002 | G7: =TEXT(F7,"mmmm") -> March | H7: =IF(E7>=40000,20%,IF(E7>=20000,10%,5%)) -> 0.05 | I7: =E7*H7 -> 987.85
A8: 2007 | B8: Mouse | C8: East | D8: Person 7 | E8: 32058 | F8: 45017 | G8: =TEXT(F8,"mmmm") -> April | H8: =IF(E8>=40000,20%,IF(E8>=20000,10%,5%)) -> 0.1 | I8: =E8*H8 -> 3205.8
A9: 2008 | B9: Keyboard | C9: East | D9: Person 8 | E9: 46429 | F9: 45032 | G9: =TEXT(F9,"mmmm") -> April | H9: =IF(E9>=40000,20%,IF(E9>=20000,10%,5%)) -> 0.2 | I9: =E9*H9 -> 9285.8
A10: 2009 | B10: Printer | C10: East | D10: Person 9 | E10: 19746 | F10: 45047 | G10: =TEXT(F10,"mmmm") -> May | H10: =IF(E10>=40000,20%,IF(E10>=20000,10%,5%)) -> 0.05 | I10: =E10*H10 -> 987.3
A11: 2010 | B11: Keyboard | C11: South | D11: Person 10 | E11: 35185 | F11: 45062 | G11: =TEXT(F11,"mmmm") -> May | H11: =IF(E11>=40000,20%,IF(E11>=20000,10%,5%)) -> 0.1 | I11: =E11*H11 -> 3518.5
A12: 2011 | B12: Keyboard | C12: East | D12: Person 11 | E12: 33920 | F12: 45077 | G12: =TEXT(F12,"mmmm") -> May | H12: =IF(E12>=40000,20%,IF(E12>=20000,10%,5%)) -> 0.1 | I12: =E12*H12 -> 3392
A13: 2012 | B13: Monitor | C13: North | D13: Person 12 | E13: 35611 | F13: 45092 | G13: =TEXT(F13,"mmmm") -> June | H13: =IF(E13>=40000,20%,IF(E13>=20000,10%,5%)) -> 0.1 | I13: =E13*H13 -> 3561.1
... A21: 2020 | B21: Printer | C21: West | D21: Person 20 | E21: 33953 | F21: 45212 | G21: =TEXT(F21,"mmmm") -> October | H21: =IF(E21>=40000,20%,IF(E21>=20000,10%,5%)) -> 0.1 | I21: =E21*H21 -> 3395.3

Sheet Students
A1: Student ID | B1: Name | C1: Math | D1: Science | E1: English | F1: Enrollment Date | G1: Average | H1: Grade | I1: Math & Science >80? | J1: All Subjects >60?
A2: 1001 | B2: Student 1 | C2: 61 | D2: 48 | E2: 76 | F2: 43101 | G2: =AVERAGE(C2:E2) -> 61.666667 | H2: =IF(G2>=90,"A",IF(G2>=75,"B",IF(G2>=60,"C","F"))) -> C | I2: =IF(AND(C2>80,D2>80),"Yes","No") -> No | J2: =IF(AND(C2>60,D2>60,E2>60),"Yes","No") -> No
A3: 1002 | B3: Student 2 | C3: 78 | D3: 76 | E3: 70 | F3: 43281 | G3: =AVERAGE(C3:E3) -> 74.666667 | H3: =IF(G3>=90,"A",IF(G3>=75,"B",IF(G3>=60,"C","F"))) -> C | I3: =IF(AND(C3>80,D3>80),"Yes","No") -> No | J3: =IF(AND(C3>60,D3>60,E3>60),"Yes","No") -> Yes
A4: 1003 | B4: Student 3 | C4: 97 | D4: 60 | E4: 51 | F4: 43461 | G4: =AVERAGE(C4:E4) -> 69.333333 | H4: =IF(G4>=90,"A",IF(G4>=75,"B",IF(G4>=60,"C","F"))) -> C | I4: =IF(AND(C4>80,D4>80),"Yes","No") -> No | J4: =IF(AND(C4>60,D4>60,E4>60),"Yes","No") -> No
A5: 1004 | B5: Student 4 | C5: 74 | D5: 55 | E5: 46 | F5: 43641 | G5: =AVERAGE(C5:E5) -> 58.333333 | H5: =IF(G5>=90,"A",IF(G5>=75,"B",IF(G5>=60,"C","F"))) -> F | I5: =IF(AND(C5>80,D5>80),"Yes","No") -> No | J5: =IF(AND(C5>60,D5>60,E5>60),"Yes","No") -> No
A6: 1005 | B6: Student 5 | C6: 68 | D6: 74 | E6: 84 | F6: 43821 | G6: =AVERAGE(C6:E6) -> 75.333333 | H6: =IF(G6>=90,"A",IF(G6>=75,"B",IF(G6>=60,"C","F"))) -> B | I6: =IF(AND(C6>80,D6>80),"Yes","No") -> No | J6: =IF(AND(C6>60,D6>60,E6>60),"Yes","No") -> Yes
A7: 1006 | B7: Student 6 | C7: 80 | D7: 70 | E7: 65 | F7: 44001 | G7: =AVERAGE(C7:E7) -> 71.666667 | H7: =IF(G7>=90,"A",IF(G7>=75,"B",IF(G7>=60,"C","F"))) -> C | I7: =IF(AND(C7>80,D7>80),"Yes","No") -> No | J7: =IF(AND(C7>60,D7>60,E7>60),"Yes","No") -> Yes
A8: 1007 | B8: Student 7 | C8: 75 | D8: 47 | E8: 78 | F8: 44181 | G8: =AVERAGE(C8:E8) -> 66.666667 | H8: =IF(G8>=90,"A",IF(G8>=75,"B",IF(G8>=60,"C","F"))) -> C | I8: =IF(AND(C8>80,D8>80),"Yes","No") -> No | J8: =IF(AND(C8>60,D8>60,E8>60),"Yes","No") -> No
A9: 1008 | B9: Student 8 | C9: 94 | D9: 67 | E9: 64 | F9: 44361 | G9: =AVERAGE(C9:E9) -> 75 | H9: =IF(G9>=90,"A",IF(G9>=75,"B",IF(G9>=60,"C","F"))) -> B | I9: =IF(AND(C9>80,D9>80),"Yes","No") -> No | J9: =IF(AND(C9>60,D9>60,E9>60),"Yes","No") -> Yes
A10: 1009 | B10: Student 9 | C10: 41 | D10: 75 | E10: 56 | F10: 44541 | G10: =AVERAGE(C10:E10) -> 57.333333 | H10: =IF(G10>=90,"A",IF(G10>=75,"B",IF(G10>=60,"C","F"))) -> F | I10: =IF(AND(C10>80,D10>80),"Yes","No") -> No | J10: =IF(AND(C10>60,D10>60,E10>60),"Yes","No") -> No
A11: 1010 | B11: Student 10 | C11: 98 | D11: 54 | E11: 58 | F11: 44721 | G11: =AVERAGE(C11:E11) -> 70 | H11: =IF(G11>=90,"A",IF(G11>=75,"B",IF(G11>=60,"C","F"))) -> C | I11: =IF(AND(C11>80,D11>80),"Yes","No") -> No | J11: =IF(AND(C11>60,D11>60,E11>60),"Yes","No") -> No
A12: 1011 | B12: Student 11 | C12: 73 | D12: 79 | E12: 53 | F12: 44901 | G12: =AVERAGE(C12:E12) -> 68.333333 | H12: =IF(G12>=90,"A",IF(G12>=75,"B",IF(G12>=60,"C","F"))) -> C | I12: =IF(AND(C12>80,D12>80),"Yes","No") -> No | J12: =IF(AND(C12>60,D12>60,E12>60),"Yes","No") -> No
A13: 1012 | B13: Student 12 | C13: 85 | D13: 89 | E13: 79 | F13: 45081 | G13: =AVERAGE(C13:E13) -> 84.333333 | H13: =IF(G13>=90,"A",IF(G13>=75,"B",IF(G13>=60,"C","F"))) -> B | I13: =IF(AND(C13>80,D13>80),"Yes","No") -> Yes | J13: =IF(AND(C13>60,D13>60,E13>60),"Yes","No") -> Yes
... A21: 1020 | B21: Student 20 | C21: 83 | D21: 92 | E21: 55 | F21: 46521 | G21: =AVERAGE(C21:E21) -> 76.666667 | H21: =IF(G21>=90,"A",IF(G21>=75,"B",IF(G21>=60,"C","F"))) -> B | I21: =IF(AND(C21>80,D21>80),"Yes","No") -> Yes | J21: =IF(AND(C21>60,D21>60,E21>60),"Yes","No") -> No

Sheet Task Solutions
A1: PR. 1 – MAIN TASKS + ESSENTIAL TASKS | READY FORMULA SHEET
A3: # | B3: Task / Concept | C3: Formula / Action | D3: Expected Result / Note | E3: Where to Apply
A4: 1 | B4: Main Task – Student Average | C4: =AVERAGE(Students!C2:E2) -> 61.666667 | D4: Example Student 13 = 95.00 | E4: Students!G2:G21
A5: 2 | B5: Main Task – Student Grade (Nested IF) | C5: =IF(Students!G2>=90,"A",IF(Students!G2>=75,"B",IF(Students!G2>=60,"C","F"))) -> C | D5: Example Student 13 = A | E5: Students!H2:H21
A6: 3 | B6: Main Task – COUNTIFS Math >60 | C6: =COUNTIFS(Students!C2:C21,">60") -> 19 | D6: 19 | E6: Task Solutions
A7: 4 | B7: Main Task – VLOOKUP Sales ID 2008 | C7: =VLOOKUP(2008,'Sales Data'!A2:F21,5,FALSE) -> 46429 | D7: 46429 | E7: Task Solutions
A8: 5 | B8: Main Task – XLOOKUP Employee 3018 | C8: =_xlfn.XLOOKUP(3018,'Employee Data'!A2:A21,'Employee Data'!D2:D21,"Not Found") -> 116284 | D8: 116284 | E8: Task Solutions
A9: 6 | B9: Main Task – FILTER Students Average >80 | C9: =_xlfn._xlws.FILTER(Students!A2:H21,Students!G2:G21>80,"No students found") -> 1012 | D9: Returns Student 12 and Student 13 rows | E9: Dynamic array
A10: 7 | B10: Essential – Relative + Absolute | C10: ='Employee Data'!D2*(1+'Employee Data'!$J$2) -> 95442.6 | D10: D2 changes when copied; $J$2 stays fixed | E10: Employee Data!H2:H21
A11: 8 | B11: Essential – IF + AND | C11: =IF(AND(Students!C2>80,Students!D2>80),"Yes","No") -> No | D11: Yes for Student 12 and 13 | E11: Students!I2:I21
A12: 9 | B12: Essential – IF + OR | C12: =IF(OR('Sales Data'!E2>=40000,'Sales Data'!B2="Laptop"),"Eligible","Not Eligible") -> Not Eligible | D12: Discount eligibility practice | E12: Sales Data
A13: 10 | B13: Essential – COUNTIFS Math >50 | C13: =COUNTIFS(Students!C2:C21,">50") -> 19 | D13: 19 | E13: Task Solutions
A14: 11 | B14: Essential – SUMIFS South + Keyboard | C14: =SUMIFS('Sales Data'!E2:E21,'Sales Data'!C2:C21,"South",'Sales Data'!B2:B21,"Keyboard") -> 42233 | D14: 42233 | E14: Task Solutions
A15: 12 | B15: Essential – AVERAGEIFS Average >60 | C15: =AVERAGEIFS(Students!G2:G21,Students!G2:G21,">60") -> 73.625 | D15: 73.625 | E15: Task Solutions
A16: 13 | B16: Essential – VLOOKUP Student ID 1008 | C16: =VLOOKUP(1008,Students!A2:F21,2,FALSE) -> Student 8 | D16: Student 8 | E16: Task Solutions
A17: 14 | B17: Essential – INDEX/MATCH Employee 3016 | C17: =INDEX('Employee Data'!D2:D21,MATCH(3016,'Employee Data'!A2:A21,0)) -> 114173 | D17: 114173 | E17: Task Solutions
A18: 15 | B18: Essential – INDEX/MATCH Person 10 in May | C18: =INDEX('Sales Data'!E2:E21,MATCH(1,('Sales Data'!D2:D21="Person 10")*('Sales Data'!G2:G21="May"),0)) -> #N/A | D18: 35185 | E18: Excel 365 / dynamic array
A19: 16 | B19: Essential – TEXT / First Name | C19: =LEFT('Employee Data'!B2,FIND(" ",'Employee Data'!B2)-1) -> Employee | D19: Employee | E19: Employee Data
A20: 17 | B20: Essential – UPPER | C20: =UPPER('Employee Data'!B2) -> EMPLOYEE 1 | D20: EMPLOYEE 1 | E20: Task Solutions
A21: 18 | B21: Essential – LOWER | C21: =LOWER('Employee Data'!B2) -> employee 1 | D21: employee 1 | E21: Task Solutions
A22: 19 | B22: Essential – XLOOKUP Employee Salary | C22: =_xlfn.XLOOKUP(3016,'Employee Data'!A2:A21,'Employee Data'!D2:D21,"Not Found") -> 114173 | D22: 114173 | E22: Task Solutions
A23: 20 | B23: Essential – XMATCH Laptop | C23: =_xlfn.XMATCH("Laptop",'Sales Data'!B2:B21,0) -> 13 | D23: 13 | E23: Position within B2:B21
A24: 21 | B24: Essential – INDIRECT | C24: =INDIRECT("'Employee Data'!"&"D5") -> 109972 | D24: Returns Employee 4 salary (109972) | E24: Dynamic cell reference
A25: 22 | B25: Essential – OFFSET | C25: =SUM(OFFSET('Sales Data'!E2,0,0,5,1)) -> 96800 | D25: Sum of first 5 Amount cells = 108800 | E25: Dynamic range
A26: 23 | B26: Essential – YEAR | C26: =YEAR('Employee Data'!E2) -> 2015 | D26: 2015 | E26: Employee Data
A27: 24 | B27: Essential – MONTH | C27: =MONTH('Employee Data'!E2) -> 1 | D27: 1 | E27: Employee Data
A28: 25 | B28: Essential – DAY | C28: =DAY('Employee Data'!E2) -> 1 | D28: 1 | E28: Employee Data
A29: 26 | B29: Essential – TEXT Date | C29: =TEXT('Employee Data'!E2,"dd-mmm-yyyy") -> 01-Jan-2015 | D29: 01-Jan-2015 | E29: Employee Data
A30: 27 | B30: Essential – Date Difference | C30: ='Employee Data'!E21-'Employee Data'!E2 -> 4750 | D30: 4750 | E30: Days between first and last employee dates
A31: 28 | B31: Essential – ROUND | C31: =ROUND('Sales Data'!E2,-2) -> 7000 | D31: 7000 | E31: 7048 rounded to nearest 100
A32: 29 | B32: Essential – CEILING | C32: =CEILING('Sales Data'!E2,1000) -> 8000 | D32: 8000 | E32: 7048 rounded up to nearest 1000
A33: 30 | B33: Essential – FLOOR | C33: =FLOOR('Sales Data'!E2,1000) -> 7000 | D33: 7000 | E33: 7048 rounded down to nearest 1000
A34: 31 | B34: Essential – FILTER Top Students | C34: =_xlfn._xlws.FILTER(Students!A2:H21,Students!G2:G21>80,"No students found") -> 1012 | D34: Student 12 and Student 13 | E34: Dynamic array
A35: 32 | B35: Essential – Age from DOB | C35: Add a Date of Birth column, then use =DATEDIF(DOB,TODAY(),"Y") | D35: DOB is not present in supplied dataset | E35: Needs DOB field
A36: 33 | B36: Essential – Product Price / Product Code | C36: Add Product Code + Price dataset, then use VLOOKUP/XLOOKUP | D36: Product Price/Product Code is not present in supplied Sales data | E36: Needs price table
A39: Project Completion Checklist
A40: ✓ Employee Data: Year, Month and Salary +10% completed
A41: ✓ Sales Data: Month, Discount % and Discount Amount completed
A42: ✓ Students: Average, Grade, AND checks completed
A43: ✓ Main Tasks covered with formulas and expected outputs
...
